Workbook

Sheet Start Here
A2: U.S. gasoline demand: reader guide
A4: Research question | B4: How are U.S. gasoline prices associated with gasoline consumption after accounting for real income and recurring seasonal patterns?
A5: Sample | B5: 192 monthly observations, January 2010–December 2025. Each row is one month. Original source values were retrieved on October 3, 2026.
A7: 1. Follow the analysis
A8: Step | B8: Worksheet | C8: Location | D8: What to check
A9: 1. Check sources | B9: Sources and Notes | C9: Rows 4–6 and 9–21 | D9: Read the series definitions, units, official links, retrieval date and data preparation notes.
A10: 2. Read the data | B10: Monthly Data | C10: A1:D193 | D10: Date, consumption proxy, gasoline price and real income. Rows 2–193 contain the 192 observations.
A11: 3. Inspect formulas | B11: Monthly Data | C11: E2:R193 | D11: Natural logs in E:G. February–December indicators in H:R. Click a cell to see its formula in Excel.
A12: 4. Read the baseline | B12: OLS Results | C12: Rows 6–30 | D12: Conventional OLS coefficients, uncertainty and model fit for all 192 months.
A13: 5. Check reliability | B13: Robustness | C13: Rows 5–31 | D13: OLS with robust standard errors and pandemic sensitivity checks. Full-sample results remain the main analysis.
A15: 2. Trace one actual observation
A16: Example month | B16: March 2010 is row 4 of Monthly Data. The values below link to that row so you can follow the source values into the regression variables.
A17: Field | B17: Cell in Monthly Data | C17: Value | D17: Meaning
A18: Date | B18: A4 | C18: ='Monthly Data'!A4 -> 40238 | D18: The first day of March identifies the month. This is not a daily observation.
A19: Consumption | B19: B4 | C19: ='Monthly Data'!B4 -> 8793 | D19: Monthly average daily rate: 8,793 thousand barrels per day. It is not the month’s total barrels.
A20: Gasoline price | B20: C4 | C20: ='Monthly Data'!C4 -> 2.772 | D20: Regular all-formulations retail price in nominal dollars per gallon.
A21: Real income | B21: D4 | C21: ='Monthly Data'!D4 -> 12340.3 | D21: Aggregate disposable income in billions of chained 2017 dollars, at a seasonally adjusted annual rate.
A22: ln(Consumption) | B22: E4 | C22: ='Monthly Data'!E4 -> 9.0817112 | D22: LN(B4) transforms consumption into its natural logarithm.
A23: ln(Price) | B23: F4 | C23: ='Monthly Data'!F4 -> 1.0195691 | D23: LN(C4) transforms price into its natural logarithm.
A24: ln(Income) | B24: G4 | C24: ='Monthly Data'!G4 -> 9.4206256 | D24: LN(D4) transforms income into its natural logarithm.
A25: March indicator | B25: I4 | C25: ='Monthly Data'!I4 -> 1 | D25: Formula: IF(MONTH($A4)=3,1,0). It returns 1 for March and 0 for other months.
A26: February indicator | B26: H4 | C26: ='Monthly Data'!H4 -> 0 | D26: Formula: IF(MONTH($A4)=2,1,0). It returns 0 here because this observation is March.
A28: 3. Understand the model
A29: ln(Q_t) = β0 + β1 ln(P_t) + β2 ln(I_t) + Σ δ_m D_m,t + ε_t (m = February,…,December)
A31: Variables | B31: Q is the gasoline consumption proxy, P is gasoline price, and I is real disposable personal income. D identifies the calendar month. β0 is the intercept and ε is the part the model does not explain.
A32: Why use logs? | B32: Logging both consumption and price lets β1 describe an approximate percentage relationship: a 1% higher price is associated with β1% different consumption, holding income and calendar month constant.
A33: Why omit January? | B33: January stays in the sample and has all eleven indicators equal to 0. Each month coefficient compares that month with January. An intercept plus all twelve month indicators would contain redundant information.
A34: What does OLS do? | B34: Ordinary least squares chooses the coefficients that minimize the sum of squared prediction errors. The original model includes 13 explanatory variables and an intercept.
A35: What does HAC do? | B35: Heteroskedasticity and autocorrelation consistent standard errors allow errors to vary in size and to be related across months. HAC changes estimated uncertainty and significance tests, while keeping the same OLS coefficients.
A36: What does HAC(12) mean? | B36: The main uncertainty check allows correlation across as many as 12 calendar months. Checks with 3 and 6 lags show whether that choice changes the conclusion. Method details are on Robustness.
A38: 4. Read the main results
A39: Analysis | B39: Price coefficient | C39: p value | D39: Interpretation
A40: Full sample: conventional OLS | B40: ='OLS Results'!B8 -> -0.0093953554 | C40: ='OLS Results'!E8 -> 0.61029045 | D40: The baseline price association is small and not statistically significant at the 5% level.
A41: Full sample: OLS with HAC(12) | B41: =Robustness!C7 -> -0.0093953554 | C41: =Robustness!E7 -> 0.89761277 | D41: Same coefficient, greater uncertainty. This is the main check accounting for correlation between months.
A42: Exclude Mar 2020–Dec 2021 | B42: =Robustness!C12 -> -0.11868111 | C42: =Robustness!E12 -> 1.5857516e-25 | D42: A stronger negative association appears after removing 22 months. Report it as a sample-sensitivity check.
A44: What is a p value? | B44: Assuming the true coefficient is zero and the testing assumptions hold, the p value measures how unusual a result at least this far from zero would be. Below 0.05 is the chosen significance threshold. A larger value does not prove that price has no effect.
A45: What is R squared? | B45: R squared describes how much variation in log consumption the model explains within this sample. The baseline value is 0.2589, or about 25.9%. It does not establish causation or forecasting accuracy.
A46: What is the conclusion? | B46: The full-sample price association is not statistically distinguishable from zero. Removing pandemic months changes the estimate substantially. Present both findings and describe the sample sensitivity.
A47: Can we claim causation? | B47: No. Observed market prices and quantities reflect both supply and demand, and omitted factors may affect both. This model describes conditional associations. Robust standard errors do not solve that identification problem.
A49: 5. Explain and reproduce the work
...

Sheet Monthly Data
A1: Date | B1: Consumption (thousand bbl/day) | C1: Gas Price ($/gallon) | D1: Real Income (bn chained 2017 $ SAAR) | E1: ln(Consumption) | F1: ln(Price) | G1: ln(Income) | H1: February dummy | I1: March dummy | J1: April dummy | K1: May dummy | L1: June dummy | M1: July dummy | N1: August dummy | O1: September dummy | P1: October dummy | Q1: November dummy | R1: December dummy
A2: 40179 | B2: 8520 | C2: 2.715 | D2: 12285.8 | E2: =LN(B2) -> 9.0501716 | F2: =LN(C2) -> 0.99879195 | G2: =LN(D2) -> 9.4161994 | H2: =IF(MONTH($A2)=2,1,0) -> 0 | I2: =IF(MONTH($A2)=3,1,0) -> 0 | J2: =IF(MONTH($A2)=4,1,0) -> 0 | K2: =IF(MONTH($A2)=5,1,0) -> 0 | L2: =IF(MONTH($A2)=6,1,0) -> 0 | M2: =IF(MONTH($A2)=7,1,0) -> 0 | N2: =IF(MONTH($A2)=8,1,0) -> 0 | O2: =IF(MONTH($A2)=9,1,0) -> 0 | P2: =IF(MONTH($A2)=10,1,0) -> 0 | Q2: =IF(MONTH($A2)=11,1,0) -> 0 | R2: =IF(MONTH($A2)=12,1,0) -> 0
A3: 40210 | B3: 8579 | C3: 2.644 | D3: 12292 | E3: =LN(B3) -> 9.0570726 | F3: =LN(C3) -> 0.97229292 | G3: =LN(D3) -> 9.4167039 | H3: =IF(MONTH($A3)=2,1,0) -> 1 | I3: =IF(MONTH($A3)=3,1,0) -> 0 | J3: =IF(MONTH($A3)=4,1,0) -> 0 | K3: =IF(MONTH($A3)=5,1,0) -> 0 | L3: =IF(MONTH($A3)=6,1,0) -> 0 | M3: =IF(MONTH($A3)=7,1,0) -> 0 | N3: =IF(MONTH($A3)=8,1,0) -> 0 | O3: =IF(MONTH($A3)=9,1,0) -> 0 | P3: =IF(MONTH($A3)=10,1,0) -> 0 | Q3: =IF(MONTH($A3)=11,1,0) -> 0 | R3: =IF(MONTH($A3)=12,1,0) -> 0
A4: 40238 | B4: 8793 | C4: 2.772 | D4: 12340.3 | E4: =LN(B4) -> 9.0817112 | F4: =LN(C4) -> 1.0195691 | G4: =LN(D4) -> 9.4206256 | H4: =IF(MONTH($A4)=2,1,0) -> 0 | I4: =IF(MONTH($A4)=3,1,0) -> 1 | J4: =IF(MONTH($A4)=4,1,0) -> 0 | K4: =IF(MONTH($A4)=5,1,0) -> 0 | L4: =IF(MONTH($A4)=6,1,0) -> 0 | M4: =IF(MONTH($A4)=7,1,0) -> 0 | N4: =IF(MONTH($A4)=8,1,0) -> 0 | O4: =IF(MONTH($A4)=9,1,0) -> 0 | P4: =IF(MONTH($A4)=10,1,0) -> 0 | Q4: =IF(MONTH($A4)=11,1,0) -> 0 | R4: =IF(MONTH($A4)=12,1,0) -> 0
A5: 40269 | B5: 9108 | C5: 2.848 | D5: 12447.1 | E5: =LN(B5) -> 9.1169084 | F5: =LN(C5) -> 1.046617 | G5: =LN(D5) -> 9.4292429 | H5: =IF(MONTH($A5)=2,1,0) -> 0 | I5: =IF(MONTH($A5)=3,1,0) -> 0 | J5: =IF(MONTH($A5)=4,1,0) -> 1 | K5: =IF(MONTH($A5)=5,1,0) -> 0 | L5: =IF(MONTH($A5)=6,1,0) -> 0 | M5: =IF(MONTH($A5)=7,1,0) -> 0 | N5: =IF(MONTH($A5)=8,1,0) -> 0 | O5: =IF(MONTH($A5)=9,1,0) -> 0 | P5: =IF(MONTH($A5)=10,1,0) -> 0 | Q5: =IF(MONTH($A5)=11,1,0) -> 0 | R5: =IF(MONTH($A5)=12,1,0) -> 0
A6: 40299 | B6: 9162 | C6: 2.836 | D6: 12540.3 | E6: =LN(B6) -> 9.1228198 | F6: =LN(C6) -> 1.0423946 | G6: =LN(D6) -> 9.4367027 | H6: =IF(MONTH($A6)=2,1,0) -> 0 | I6: =IF(MONTH($A6)=3,1,0) -> 0 | J6: =IF(MONTH($A6)=4,1,0) -> 0 | K6: =IF(MONTH($A6)=5,1,0) -> 1 | L6: =IF(MONTH($A6)=6,1,0) -> 0 | M6: =IF(MONTH($A6)=7,1,0) -> 0 | N6: =IF(MONTH($A6)=8,1,0) -> 0 | O6: =IF(MONTH($A6)=9,1,0) -> 0 | P6: =IF(MONTH($A6)=10,1,0) -> 0 | Q6: =IF(MONTH($A6)=11,1,0) -> 0 | R6: =IF(MONTH($A6)=12,1,0) -> 0
A7: 40330 | B7: 9311 | C7: 2.732 | D7: 12544.3 | E7: =LN(B7) -> 9.1389518 | F7: =LN(C7) -> 1.0050339 | G7: =LN(D7) -> 9.4370217 | H7: =IF(MONTH($A7)=2,1,0) -> 0 | I7: =IF(MONTH($A7)=3,1,0) -> 0 | J7: =IF(MONTH($A7)=4,1,0) -> 0 | K7: =IF(MONTH($A7)=5,1,0) -> 0 | L7: =IF(MONTH($A7)=6,1,0) -> 1 | M7: =IF(MONTH($A7)=7,1,0) -> 0 | N7: =IF(MONTH($A7)=8,1,0) -> 0 | O7: =IF(MONTH($A7)=9,1,0) -> 0 | P7: =IF(MONTH($A7)=10,1,0) -> 0 | Q7: =IF(MONTH($A7)=11,1,0) -> 0 | R7: =IF(MONTH($A7)=12,1,0) -> 0
A8: 40360 | B8: 9301 | C8: 2.729 | D8: 12554.2 | E8: =LN(B8) -> 9.1378772 | F8: =LN(C8) -> 1.0039352 | G8: =LN(D8) -> 9.4378105 | H8: =IF(MONTH($A8)=2,1,0) -> 0 | I8: =IF(MONTH($A8)=3,1,0) -> 0 | J8: =IF(MONTH($A8)=4,1,0) -> 0 | K8: =IF(MONTH($A8)=5,1,0) -> 0 | L8: =IF(MONTH($A8)=6,1,0) -> 0 | M8: =IF(MONTH($A8)=7,1,0) -> 1 | N8: =IF(MONTH($A8)=8,1,0) -> 0 | O8: =IF(MONTH($A8)=9,1,0) -> 0 | P8: =IF(MONTH($A8)=10,1,0) -> 0 | Q8: =IF(MONTH($A8)=11,1,0) -> 0 | R8: =IF(MONTH($A8)=12,1,0) -> 0
A9: 40391 | B9: 9255 | C9: 2.73 | D9: 12591.4 | E9: =LN(B9) -> 9.1329192 | F9: =LN(C9) -> 1.0043016 | G9: =LN(D9) -> 9.4407693 | H9: =IF(MONTH($A9)=2,1,0) -> 0 | I9: =IF(MONTH($A9)=3,1,0) -> 0 | J9: =IF(MONTH($A9)=4,1,0) -> 0 | K9: =IF(MONTH($A9)=5,1,0) -> 0 | L9: =IF(MONTH($A9)=6,1,0) -> 0 | M9: =IF(MONTH($A9)=7,1,0) -> 0 | N9: =IF(MONTH($A9)=8,1,0) -> 1 | O9: =IF(MONTH($A9)=9,1,0) -> 0 | P9: =IF(MONTH($A9)=10,1,0) -> 0 | Q9: =IF(MONTH($A9)=11,1,0) -> 0 | R9: =IF(MONTH($A9)=12,1,0) -> 0
A10: 40422 | B10: 9112 | C10: 2.705 | D10: 12589.9 | E10: =LN(B10) -> 9.1173475 | F10: =LN(C10) -> 0.99510191 | G10: =LN(D10) -> 9.4406502 | H10: =IF(MONTH($A10)=2,1,0) -> 0 | I10: =IF(MONTH($A10)=3,1,0) -> 0 | J10: =IF(MONTH($A10)=4,1,0) -> 0 | K10: =IF(MONTH($A10)=5,1,0) -> 0 | L10: =IF(MONTH($A10)=6,1,0) -> 0 | M10: =IF(MONTH($A10)=7,1,0) -> 0 | N10: =IF(MONTH($A10)=8,1,0) -> 0 | O10: =IF(MONTH($A10)=9,1,0) -> 1 | P10: =IF(MONTH($A10)=10,1,0) -> 0 | Q10: =IF(MONTH($A10)=11,1,0) -> 0 | R10: =IF(MONTH($A10)=12,1,0) -> 0
A11: 40452 | B11: 9016 | C11: 2.801 | D11: 12592.5 | E11: =LN(B11) -> 9.1067561 | F11: =LN(C11) -> 1.0299765 | G11: =LN(D11) -> 9.4408567 | H11: =IF(MONTH($A11)=2,1,0) -> 0 | I11: =IF(MONTH($A11)=3,1,0) -> 0 | J11: =IF(MONTH($A11)=4,1,0) -> 0 | K11: =IF(MONTH($A11)=5,1,0) -> 0 | L11: =IF(MONTH($A11)=6,1,0) -> 0 | M11: =IF(MONTH($A11)=7,1,0) -> 0 | N11: =IF(MONTH($A11)=8,1,0) -> 0 | O11: =IF(MONTH($A11)=9,1,0) -> 0 | P11: =IF(MONTH($A11)=10,1,0) -> 1 | Q11: =IF(MONTH($A11)=11,1,0) -> 0 | R11: =IF(MONTH($A11)=12,1,0) -> 0
A12: 40483 | B12: 8816 | C12: 2.859 | D12: 12605.1 | E12: =LN(B12) -> 9.0843235 | F12: =LN(C12) -> 1.0504719 | G12: =LN(D12) -> 9.4418568 | H12: =IF(MONTH($A12)=2,1,0) -> 0 | I12: =IF(MONTH($A12)=3,1,0) -> 0 | J12: =IF(MONTH($A12)=4,1,0) -> 0 | K12: =IF(MONTH($A12)=5,1,0) -> 0 | L12: =IF(MONTH($A12)=6,1,0) -> 0 | M12: =IF(MONTH($A12)=7,1,0) -> 0 | N12: =IF(MONTH($A12)=8,1,0) -> 0 | O12: =IF(MONTH($A12)=9,1,0) -> 0 | P12: =IF(MONTH($A12)=10,1,0) -> 0 | Q12: =IF(MONTH($A12)=11,1,0) -> 1 | R12: =IF(MONTH($A12)=12,1,0) -> 0
A13: 40513 | B13: 8911 | C13: 2.993 | D13: 12680.6 | E13: =LN(B13) -> 9.0950417 | F13: =LN(C13) -> 1.0962762 | G13: =LN(D13) -> 9.4478285 | H13: =IF(MONTH($A13)=2,1,0) -> 0 | I13: =IF(MONTH($A13)=3,1,0) -> 0 | J13: =IF(MONTH($A13)=4,1,0) -> 0 | K13: =IF(MONTH($A13)=5,1,0) -> 0 | L13: =IF(MONTH($A13)=6,1,0) -> 0 | M13: =IF(MONTH($A13)=7,1,0) -> 0 | N13: =IF(MONTH($A13)=8,1,0) -> 0 | O13: =IF(MONTH($A13)=9,1,0) -> 0 | P13: =IF(MONTH($A13)=10,1,0) -> 0 | Q13: =IF(MONTH($A13)=11,1,0) -> 0 | R13: =IF(MONTH($A13)=12,1,0) -> 1
... A193: 45992 | B193: 8858 | C193: 2.894 | D193: 18208.6 | E193: =LN(B193) -> 9.0890763 | F193: =LN(C193) -> 1.0626396 | G193: =LN(D193) -> 9.8096493 | H193: =IF(MONTH($A193)=2,1,0) -> 0 | I193: =IF(MONTH($A193)=3,1,0) -> 0 | J193: =IF(MONTH($A193)=4,1,0) -> 0 | K193: =IF(MONTH($A193)=5,1,0) -> 0 | L193: =IF(MONTH($A193)=6,1,0) -> 0 | M193: =IF(MONTH($A193)=7,1,0) -> 0 | N193: =IF(MONTH($A193)=8,1,0) -> 0 | O193: =IF(MONTH($A193)=9,1,0) -> 0 | P193: =IF(MONTH($A193)=10,1,0) -> 0 | Q193: =IF(MONTH($A193)=11,1,0) -> 0 | R193: =IF(MONTH($A193)=12,1,0) -> 1

Sheet OLS Results
A1: U.S. gasoline demand: baseline OLS
A3: Sample: January 2010 through December 2025. January is the reference month.
A4: ln(Q) = intercept + β1 ln(P) + β2 ln(I) + February–December controls + error
A6: Term | B6: Coefficient | C6: Std. error | D6: t statistic | E6: p value | F6: 95% lower | G6: 95% upper
A7: Intercept | B7: 9.5649533 | C7: 0.27952951 | D7: 34.218045 | E7: 3.3604222e-80 | F7: 9.0133351 | G7: 10.116572
A8: ln(Price) | B8: -0.0093953554 | C8: 0.018401991 | D8: -0.51056191 | E8: 0.61029045 | F8: -0.045709492 | G8: 0.026918781
A9: ln(Income) | B9: -0.053996322 | C9: 0.028944582 | D9: -1.865507 | E9: 0.063755938 | F9: -0.11111501 | G9: 0.003122364
A10: February | B10: 0.034361758 | C10: 0.017730216 | D10: 1.9380339 | E10: 0.054201298 | F10: -0.00062671044 | G10: 0.069350227
A11: March | B11: 0.054601666 | C11: 0.01778169 | D11: 3.0706679 | E11: 0.0024708054 | F11: 0.019511618 | G11: 0.089691713
A12: April | B12: 0.04337306 | C12: 0.017812398 | D12: 2.4349927 | E12: 0.015878651 | F12: 0.0082224138 | G12: 0.078523706
A13: May | B13: 0.075981033 | C13: 0.017852428 | D13: 4.2560615 | E13: 3.3599476e-05 | F13: 0.040751392 | G13: 0.11121067
A14: June | B14: 0.099545818 | C14: 0.017860599 | D14: 5.5734872 | E14: 9.1164588e-08 | F14: 0.064300054 | G14: 0.13479158
A15: July | B15: 0.092474802 | C15: 0.017841497 | D15: 5.1831303 | E15: 5.8789388e-07 | F15: 0.057266733 | G15: 0.12768287
A16: August | B16: 0.10209171 | C16: 0.017822143 | D16: 5.7283631 | E16: 4.2472676e-08 | F16: 0.066921832 | G16: 0.13726159
A17: September | B17: 0.068163181 | C17: 0.017809055 | D17: 3.8274451 | E17: 0.00017911057 | F17: 0.033019132 | G17: 0.10330723
A18: October | B18: 0.069244703 | C18: 0.017782556 | D18: 3.8939679 | E18: 0.00013933631 | F18: 0.034152946 | G18: 0.10433646
... A20: December | B20: 0.048694179 | C20: 0.01773539 | D20: 2.7455939 | E20: 0.0066602079 | F20: 0.013695499 | G20: 0.083692859
A23: Model statistics | B23: Value | D23: ANOVA | E23: df | F23: Sum of squares | G23: Mean square
A24: Observations | B24: 192 | D24: Regression | E24: 13 | F24: 0.15628059 | G24: 0.012021584
A25: Residual degrees of freedom | B25: 178 | D25: Residual | E25: 178 | F25: 0.44746193 | G25: 0.0025138311
A26: R squared | B26: 0.25885305 | D26: Total | E26: 191 | F26: 0.60374252
A27: Adjusted R squared | B27: 0.20472434
A28: Regression standard error | B28: 0.05013812
A29: F statistic | B29: 4.7821766
A30: Significance F | B30: 4.1799913e-07
A33: Saved OLS estimates | B33: These are saved numerical OLS estimates. Excel formulas create the logs and month indicators. Rerun the regression after changing any input. Read Start Here for a guide.
A35: Price interpretation | B35: A 1% higher gasoline price is associated with approximately 0.0094% lower consumption, holding income and calendar month constant. This full-sample estimate is not significant.
A37: Statistical inference | B37: Conventional OLS standard errors assume homoskedastic, uncorrelated errors. Price is not significant at 5% under these assumptions.
A39: Time-series limitation | B39: Durbin–Watson = 0.487 suggests positive residual correlation across months. The completed HAC and pandemic sensitivity checks are on Robustness.
A41: Rerun in Excel | B41: Data → Data Analysis → Regression. Y: Monthly Data!E1:E193. X: Monthly Data!F1:R193. Select Labels, leave Constant is Zero unchecked, and choose a new output sheet.
A43: Model scope | B43: Nominal gasoline price and real aggregate income follow the requested specification. This observational regression does not establish a causal demand elasticity.

Sheet Robustness
A1: Gasoline demand: reliability checks
A3: OLS coefficients with different standard errors and samples. Start Here explains the terms.
A5: Model / inference | B5: N | C5: Price coefficient | D5: Price SE | E5: Price p value | F5: Price 95% lower | G5: Price 95% upper | H5: Income coefficient | I5: Income SE | J5: Income p value | K5: R squared | L5: HAC lags
A6: Full sample: conventional OLS | B6: 192 | C6: -0.0093953554 | D6: 0.018401991 | E6: 0.61029045 | F6: -0.045709492 | G6: 0.026918781 | H6: -0.053996322 | I6: 0.028944582 | J6: 0.063755938 | K6: 0.25885305
A7: Full sample: OLS with HAC(12) | B7: 192 | C7: -0.0093953554 | D7: 0.073014703 | E7: 0.89761277 | F7: -0.15250154 | G7: 0.13371083 | H7: -0.053996322 | I7: 0.063297454 | J7: 0.39362783 | K7: 0.25885305 | L7: 12
A8: Full sample: OLS with HAC(6) | B8: 192 | C8: -0.0093953554 | D8: 0.063685341 | E8: 0.88271547 | F8: -0.13421633 | G8: 0.11542562 | H8: -0.053996322 | I8: 0.053331477 | J8: 0.31131517 | K8: 0.25885305 | L8: 6
A9: Full sample: OLS with HAC(3) | B9: 192 | C9: -0.0093953554 | D9: 0.055365243 | E9: 0.86524787 | F9: -0.11790924 | G9: 0.099118527 | H9: -0.053996322 | I9: 0.046124632 | J9: 0.24173495 | K9: 0.25885305 | L9: 3
A10: Full sample: OLS with HC1 | B10: 192 | C10: -0.0093953554 | D10: 0.035082914 | E10: 0.78884996 | F10: -0.078156604 | G10: 0.059365893 | H10: -0.053996322 | I10: 0.030562208 | J10: 0.077267144 | K10: 0.25885305 | L10: 0
A11: Add pandemic indicator: HAC(12) | B11: 192 | C11: -0.051018283 | D11: 0.042841779 | E11: 0.2337111 | F11: -0.13498663 | G11: 0.032950061 | H11: 0.032280457 | I11: 0.030304447 | J11: 0.28678305 | K11: 0.48933382 | L11: 12
A12: Exclude Mar 2020–Dec 2021: HAC(12) | B12: 170 | C12: -0.11868111 | D12: 0.011365199 | E12: 1.5857516e-25 | F12: -0.14095649 | G12: -0.096405733 | H12: 0.047789384 | I12: 0.019023657 | J12: 0.01200141 | K12: 0.85173969 | L12: 12
A13: Exclude Mar–Dec 2020: HAC(12) | B13: 182 | C13: -0.10879528 | D13: 0.014825632 | E13: 2.1628554e-13 | F13: -0.13785299 | G13: -0.07973758 | H13: 0.020284886 | I13: 0.027365687 | J13: 0.45854031 | K13: 0.75493279 | L13: 12
A14: Exclude Mar 2020–Jun 2021: HAC(12) | B14: 176 | C14: -0.11775389 | D14: 0.011470984 | E14: 1.0093342e-24 | F14: -0.14023661 | G14: -0.095271179 | H14: 0.04752361 | I14: 0.018345386 | J14: 0.0095838313 | K14: 0.8470719 | L14: 12
A17: Full sample: OLS with HAC(12) | B17: Coefficient | C17: Robust SE | D17: z statistic | E17: p value | F17: 95% lower | G17: 95% upper
A18: Intercept | B18: 9.5649533 | C18: 0.55295912 | D18: 17.297759 | E18: 4.8904865e-67 | F18: 8.4811734 | G18: 10.648733
A19: ln(Price) | B19: -0.0093953554 | C19: 0.073014703 | D19: -0.12867758 | E19: 0.89761277 | F19: -0.15250154 | G19: 0.13371083
A20: ln(Income) | B20: -0.053996322 | C20: 0.063297454 | D20: -0.85305676 | E20: 0.39362783 | F20: -0.17805705 | G20: 0.070064409
A21: February | B21: 0.034361758 | C21: 0.0061318784 | D21: 5.6037899 | E21: 2.0971487e-08 | F21: 0.022343497 | G21: 0.046380019
A22: March | B22: 0.054601666 | C22: 0.015559904 | D22: 3.5091261 | E22: 0.00044958177 | F22: 0.024104814 | G22: 0.085098518
A23: April | B23: 0.04337306 | C23: 0.032606803 | D23: 1.3301844 | E23: 0.18345753 | F23: -0.020535099 | G23: 0.10728122
A24: May | B24: 0.075981033 | C24: 0.022999685 | D24: 3.3035685 | E24: 0.00095462656 | F24: 0.030902479 | G24: 0.12105959
A25: June | B25: 0.099545818 | C25: 0.015593276 | D25: 6.3838936 | E25: 1.7264107e-10 | F25: 0.068983558 | G25: 0.13010808
A26: July | B26: 0.092474802 | C26: 0.012900825 | D26: 7.1681308 | E26: 7.6028631e-13 | F26: 0.067189649 | G26: 0.11775995
A27: August | B27: 0.10209171 | C27: 0.011687932 | D27: 8.7347969 | E27: 2.440943e-18 | F27: 0.079183784 | G27: 0.12499963
A28: September | B28: 0.068163181 | C28: 0.010124906 | D28: 6.7322285 | E28: 1.6708402e-11 | F28: 0.048318729 | G28: 0.088007632
A29: October | B29: 0.069244703 | C29: 0.008596299 | D29: 8.0551762 | E29: 7.9364395e-16 | F29: 0.052396267 | G29: 0.086093139
... A31: December | B31: 0.048694179 | C31: 0.0069667458 | D31: 6.9895156 | E31: 2.7583685e-12 | F31: 0.035039608 | G31: 0.06234875
A34: Main finding | B34: The full-sample price estimate is −0.0094. HAC 12 raises its standard error from 0.0184 to 0.0730 and gives p = 0.8976. Neither price nor income is significant at 5% with HAC 12.
A36: Pandemic sensitivity | B36: Excluding March 2020–December 2021 leaves 170 observations. Price is −0.1187, with a 95% HAC interval of [−0.1410, −0.0964]. A 1% higher price is associated with approximately 0.119% lower consumption in this restricted sample.
A38: Alternative pandemic windows | B38: Excluding March–December 2020 yields −0.1088. Excluding March 2020–June 2021 yields −0.1178. Both are significant at 5% with HAC 12. These exploratory comparisons are not adjustments for multiple testing.
A40: Indicator specification | B40: Adds one dummy equal to 1 for March 2020–December 2021 to the full-sample model. Price is −0.0510 (p = 0.2337), so an additive pandemic indicator does not produce a significant full-sample price estimate.
A42: HAC method | B42: Newey–West covariance with Bartlett weights w(l) = 1 − l/(L+1), maximum lag L and correction n/(n−k). HAC 12 covers up to one year. HAC 3 and 6 test bandwidth sensitivity. HC1 allows heteroskedasticity only.
A44: Inference | B44: HAC/HC1 p values are two-sided asymptotic normal tests. The 95% intervals use 1.959964 × robust SE. Conventional OLS uses t tests with 178 df. HAC changes uncertainty, not OLS coefficients or R squared.
A46: Calendar gaps | B46: For excluded samples, lag distances use original calendar months. Scores for omitted months are zero, so February 2020 and January 2022 are not treated as adjacent observations. The correction uses the retained sample size.
A48: Calculation and verification | B48: Numerical least squares using the workbook’s unrounded source values. Verified full-sample coefficient agreement, full rank, residual orthogonality and HAC covariance agreement with an independently constructed calendar-time kernel matrix.
A50: Paper interpretation | B50: Keep the full sample as the primary result and present pandemic exclusions as sensitivity tests. The significant restricted-sample relationship has magnitude below one but does not establish a causal demand elasticity. HAC does not resolve endogeneity or model misspecification.
A52: Source and refresh | B52: Original data sources and retrieval dates remain in Sources and Notes. These are fixed estimates and require recalculation after data edits. Method reference: https://www.statsmodels.org/dev/generated/statsmodels.stats.sandwich_covariance.cov_hac.html

Sheet Sources and Notes
A1: Sources and methodology
A3: Variable / provider | B3: Series / definition | C3: Units / frequency | D3: Official source URL
A4: Gas Price / EIA | B4: U.S. Regular All Formulations Retail Gasoline Price. EMM_EPMR_PTE_NUS_DPG. | C4: Dollars per gallon. Monthly. Nominal, not seasonally adjusted. | D4: https://www.eia.gov/dnav/pet/hist/LeafHandler.ashx?n=PET&s=EMM_EPMR_PTE_NUS_DPG&f=M
A5: Consumption / EIA | B5: U.S. Product Supplied of Finished Motor Gasoline. MGFUPUS2. | C5: Thousand barrels per day. Monthly average, not seasonally adjusted. | D5: https://www.eia.gov/dnav/pet/hist/LeafHandler.ashx?n=PET&s=MGFUPUS2&f=M
A6: Real Income / BEA via FRED | B6: Real Disposable Personal Income. DSPIC96. BEA account A067RX. | C6: Billions of chained 2017 dollars. Monthly, seasonally adjusted annual rate. | D6: https://fred.stlouisfed.org/series/DSPIC96
A9: Retrieved | B9: October 3, 2026 (America/New_York). Current revised data vintage.
A10: Source updates | B10: EIA price: September 29, 2026. EIA consumption: September 30, 2026. FRED income: September 30, 2026.
A11: FRED download | B11: https://fred.stlouisfed.org/graph/fredgraph.csv?id=DSPIC96&cosd=2010-01-01&coed=2025-12-01
A12: Join and coverage | B12: Joined on calendar year/month. Date is first day of month. Exactly 192 unique consecutive months, January 2010–December 2025. All three series complete and positive.
A13: Source handling | B13: EIA values transcribed programmatically from official monthly HTML tables. FRED values read from its official CSV. No interpolation, imputation, deflation or annual-rate conversion.
A14: Consumption definition | B14: Product supplied is the requested proxy for consumption. It covers finished motor gasoline across grades, whereas price represents regular gasoline. It is a flow rate, not a monthly volume total.
A15: Income definition | B15: Aggregate real disposable personal income is retained as published. It is not per-capita income. SAAR is not divided by 12.
A16: Transformations | B16: E:G contain Excel LN formulas. H:R contain IF(MONTH(Date)=month,1,0). January has all 11 dummies equal to zero.
A17: OLS method | B17: 192 observations, 13 regressors plus intercept. Numerical least squares on the unrounded natural logs. Conventional covariance = residual variance × inverse(X transpose X). Two-sided t tests and 95% t confidence intervals, 178 residual df.
A18: Results refresh | B18: OLS Results contains fixed numerical estimates, not live regression formulas. Changes to data update the logs and dummies but require rerunning Regression in Excel.
A19: Excel formula alternative | B19: Enter =LINEST('Monthly Data'!E2:E193,'Monthly Data'!F2:R193,TRUE,TRUE) in an empty area. LINEST returns coefficients in reverse X-column order with intercept last.
A20: Paper limitations | B20: Monthly controls address recurring seasonality. The specification does not include trends, pandemic indicators or instruments. Serial correlation, endogeneity and the nominal-price/real-income mix limit interpretation.
A21: Validation | B21: Confirmed 192 records per series, exact matching date sets, positive inputs and complete monthly sequence. Checked January 2010 and December 2025 endpoints, April 2020 consumption 5,866 and June 2022 price 4.929.
